
== cat /etc/issue ===============================================
Linux mike-thinks 4.13.0-43-generic #48~16.04.1-Ubuntu SMP Thu May 17 12:56:46 UTC 2018 x86_64 x86_64 x86_64 GNU/Linux
VERSION="16.04.3 LTS (Xenial Xerus)"
VERSION_ID="16.04"
VERSION_CODENAME=xenial

== are we in docker =============================================
No

== compiler =====================================================
c++ (Ubuntu 5.4.0-6ubuntu1~16.04.9) 5.4.0 20160609
Copyright (C) 2015 Free Software Foundation, Inc.
This is free software; see the source for copying conditions.  There is NO
warranty; not even for MERCHANTABILITY or FITNESS FOR A PARTICULAR PURPOSE.


== uname -a =====================================================
Linux mike-thinks 4.13.0-43-generic #48~16.04.1-Ubuntu SMP Thu May 17 12:56:46 UTC 2018 x86_64 x86_64 x86_64 GNU/Linux

== check pips ===================================================
msgpack-numpy            0.4.1      
numpy                    1.14.3     
protobuf                 3.5.2.post1
tensorflow               1.8.0      

== check for virtualenv =========================================
False

== tensorflow import ============================================
Traceback (most recent call last):
  File "/home/mike/Programing/Rasa/myflaskapp/myFlaskAppenv/lib/python3.5/site-packages/tensorflow/python/pywrap_tensorflow_internal.py", line 18, in swig_import_helper
    fp, pathname, description = imp.find_module('_pywrap_tensorflow_internal', [dirname(__file__)])
  File "/usr/lib/python3.5/imp.py", line 296, in find_module
    raise ImportError(_ERR_MSG.format(name), name=name)
ImportError: No module named '_pywrap_tensorflow_internal'

During handling of the above exception, another exception occurred:

Traceback (most recent call last):
  File "/home/mike/Programing/Rasa/myflaskapp/myFlaskAppenv/lib/python3.5/site-packages/tensorflow/python/pywrap_tensorflow.py", line 58, in <module>
    from tensorflow.python.pywrap_tensorflow_internal import *
  File "/home/mike/Programing/Rasa/myflaskapp/myFlaskAppenv/lib/python3.5/site-packages/tensorflow/python/pywrap_tensorflow_internal.py", line 28, in <module>
    _pywrap_tensorflow_internal = swig_import_helper()
  File "/home/mike/Programing/Rasa/myflaskapp/myFlaskAppenv/lib/python3.5/site-packages/tensorflow/python/pywrap_tensorflow_internal.py", line 20, in swig_import_helper
    import _pywrap_tensorflow_internal
ImportError: No module named '_pywrap_tensorflow_internal'

During handling of the above exception, another exception occurred:

Traceback (most recent call last):
  File "<string>", line 1, in <module>
  File "/home/mike/Programing/Rasa/myflaskapp/myFlaskAppenv/lib/python3.5/site-packages/tensorflow/__init__.py", line 24, in <module>
    from tensorflow.python import pywrap_tensorflow  # pylint: disable=unused-import
  File "/home/mike/Programing/Rasa/myflaskapp/myFlaskAppenv/lib/python3.5/site-packages/tensorflow/python/__init__.py", line 49, in <module>
    from tensorflow.python import pywrap_tensorflow
  File "/home/mike/Programing/Rasa/myflaskapp/myFlaskAppenv/lib/python3.5/site-packages/tensorflow/python/pywrap_tensorflow.py", line 74, in <module>
    raise ImportError(msg)
ImportError: Traceback (most recent call last):
  File "/home/mike/Programing/Rasa/myflaskapp/myFlaskAppenv/lib/python3.5/site-packages/tensorflow/python/pywrap_tensorflow_internal.py", line 18, in swig_import_helper
    fp, pathname, description = imp.find_module('_pywrap_tensorflow_internal', [dirname(__file__)])
  File "/usr/lib/python3.5/imp.py", line 296, in find_module
    raise ImportError(_ERR_MSG.format(name), name=name)
ImportError: No module named '_pywrap_tensorflow_internal'

During handling of the above exception, another exception occurred:

Traceback (most recent call last):
  File "/home/mike/Programing/Rasa/myflaskapp/myFlaskAppenv/lib/python3.5/site-packages/tensorflow/python/pywrap_tensorflow.py", line 58, in <module>
    from tensorflow.python.pywrap_tensorflow_internal import *
  File "/home/mike/Programing/Rasa/myflaskapp/myFlaskAppenv/lib/python3.5/site-packages/tensorflow/python/pywrap_tensorflow_internal.py", line 28, in <module>
    _pywrap_tensorflow_internal = swig_import_helper()
  File "/home/mike/Programing/Rasa/myflaskapp/myFlaskAppenv/lib/python3.5/site-packages/tensorflow/python/pywrap_tensorflow_internal.py", line 20, in swig_import_helper
    import _pywrap_tensorflow_internal
ImportError: No module named '_pywrap_tensorflow_internal'


Failed to load the native TensorFlow runtime.

See https://www.tensorflow.org/install/install_sources#common_installation_problems

for some common reasons and solutions.  Include the entire stack trace
above this error message when asking for help.

== env ==========================================================
LD_LIBRARY_PATH is unset
DYLD_LIBRARY_PATH is unset

== nvidia-smi ===================================================
./tf_env_collect.sh: line 105: nvidia-smi: command not found

== cuda libs  ===================================================
